<robot xmlns:xacro="http://www.ros.org/wiki/xacro" name="xMateCR12">
  <!-- Constants for robot dimensions -->
  <material name="black">
    <color rgba="0.0 0.0 0.0 1.0"/>
  </material>
  <material name="blue">
    <color rgba="0.0 0.0 0.8 1.0"/>
  </material>
  <material name="green">
    <color rgba="0.0 0.8 0.0 1.0"/>
  </material>
  <material name="grey">
    <color rgba="0.2 0.2 0.2 1.0"/>
  </material>
  <material name="orange">
    <color rgba="1.0 0.423529411765 0.0392156862745 1.0"/>
  </material>
  <material name="brown">
    <color rgba="0.870588235294 0.811764705882 0.764705882353 1.0"/>
  </material>
  <material name="red">
    <color rgba="0.8 0.0 0.0 1.0"/>
  </material>
  <material name="white">
    <color rgba="1.0 1.0 1.0 1.0"/>
  </material>
  <material name="Beige">
    <color rgba="1.0 0.784 0.5765 1.0"/>
  </material>
  <!-- Used for fixing robot to Gazebo 'base_link' -->
  <link name="world"/>
  <joint name="fixed" type="fixed">
    <parent link="world"/>
    <child link="xMateCR12_base"/>
  </joint>
  <!--base-->
  <link name="xMateCR12_base">
    <visual>
      <geometry>
        <mesh filename="package://xMateCR12_description/meshes/xMateCR12_base.stl" scale="0.001 0.001 0.001"/>
      </geometry>
      <origin rpy="0 0 0" xyz="0.0 0.0 0.0"/>
      <material name="white"/>
    </visual>
    <inertial>
      <mass value="10.295"/>
      <inertia ixx="147.74152800" ixy="-0.02989400" ixz="0.08076300" iyy="109.35612400" iyz="42.37622800" izz="84.99320000"/>
      <origin rpy="0 0 0" xyz="0.061 49.726 268.341"/>
    </inertial>
    <collision>
      <geometry>
        <mesh filename="package://xMateCR12_description/meshes/xMateCR12_base.stl" scale="0.001 0.001 0.001"/>
      </geometry>
      <origin rpy="0 0 0" xyz="0.0 0.0 0.0"/>
    </collision>
  </link>
  <joint name="xMateCR12_joint_1" type="revolute">
    <parent link="xMateCR12_base"/>
    <child link="xMateCR12_link1"/>
    <limit effort="436" lower="-3.0543" upper="3.0543" velocity="12.0"/>
    <axis xyz="0 0 1"/>
    <origin rpy="0 0 0" xyz="0.0 0.0 0.0"/>
  </joint>
  <transmission name="tran1">
    <type>transmission_interface/SimpleTransmission</type>
    <joint name="xMateCR12_joint_7">
      <hardwareInterface>EffortJointInterface</hardwareInterface>
    </joint>
    <actuator name="motor1">
      <hardwareInterface>EffortJointInterface</hardwareInterface>
      <mechanicalReduction>1</mechanicalReduction>
    </actuator>
  </transmission>
  <!--link 1-->
  <link name="xMateCR12_link1">
    <visual>
      <geometry>
        <mesh filename="package://xMateCR12_description/meshes/xMateCR12_link1.stl" scale="0.001 0.001 0.001"/>
      </geometry>
      <origin rpy="0 0 0" xyz="0 0 0"/>
      <material name="white"/>
    </visual>
    <inertial>
      <mass value="10.295"/>
      <inertia ixx="147.74152800" ixy="-0.02989400" ixz="0.08076300" iyy="109.35612400" iyz="42.37622800" izz="84.99320000"/>
      <origin rpy="0 0 0" xyz="0.061 49.726 268.341"/>
    </inertial>
    <collision>
      <geometry>
        <mesh filename="package://xMateCR12_description/meshes/xMateCR12_link1.stl" scale="0.001 0.001 0.001"/>
      </geometry>
      <origin rpy="0 0 0" xyz="0 0 0"/>
    </collision>
  </link>
  <joint name="xMateCR12_joint_2" type="revolute">
    <parent link="xMateCR12_link1"/>
    <child link="xMateCR12_link2"/>
    <limit effort="436" lower="-2.9671" upper="2.9671" velocity="12.0"/>
    <axis xyz="0 1 0"/>
    <origin rpy="0 0 0" xyz="0.0 0.0 0.35"/>
  </joint>
  <transmission name="tran2">
    <type>transmission_interface/SimpleTransmission</type>
    <joint name="xmate_joint_2">
      <hardwareInterface>EffortJointInterface</hardwareInterface>
    </joint>
    <actuator name="motor2">
      <hardwareInterface>EffortJointInterface</hardwareInterface>
      <mechanicalReduction>1</mechanicalReduction>
    </actuator>
  </transmission>
  <!--link 2-->
  <link name="xMateCR12_link2">
    <visual>
      <geometry>
        <mesh filename="package://xMateCR12_description/meshes/xMateCR12_link2.stl" scale="0.001 0.001 0.001"/>
      </geometry>
      <origin rpy="0 0 0" xyz="0 0 0.0"/>
      <material name="white"/>
    </visual>
    <inertial>
      <mass value="13.562"/>
      <inertia ixx="1437.08381500" ixy="0.02406200" ixz="2.08568500" iyy="1436.45384900" iyz="5.26655100" izz="58.19355500"/>
      <origin rpy="0 0 0" xyz="-0.544 171.676 327.091"/>
    </inertial>
    <collision>
      <geometry>
        <mesh filename="package://xMateCR12_description/meshes/xMateCR12_link2.stl" scale="0.001 0.001 0.001"/>
      </geometry>
      <origin rpy="0 0 0" xyz="0 0 0.0"/>
    </collision>
  </link>
  <joint name="xMateCR12_joint_3" type="revolute">
    <parent link="xMateCR12_link2"/>
    <child link="xMateCR12_link3"/>
    <limit effort="194" lower="-3.0543" upper="3.0543" velocity="18.0"/>
    <axis xyz="0 -1 0"/>
    <origin rpy="0 0 0" xyz="0.0 0.0 0.76"/>
  </joint>
  <transmission name="tran3">
    <type>transmission_interface/SimpleTransmission</type>
    <joint name="xmate_joint_3">
      <hardwareInterface>EffortJointInterface</hardwareInterface>
    </joint>
    <actuator name="motor3">
      <hardwareInterface>EffortJointInterface</hardwareInterface>
      <mechanicalReduction>1</mechanicalReduction>
    </actuator>
  </transmission>
  <!--link 3-->
  <link name="xMateCR12_link3">
    <visual>
      <geometry>
        <mesh filename="package://xMateCR12_description/meshes/xMateCR12_link3.stl" scale="0.001 0.001 0.001"/>
      </geometry>
      <origin rpy="0 0 0" xyz="0 0 0"/>
      <material name="white"/>
    </visual>
    <inertial>
      <mass value="4.659"/>
      <inertia ixx="52.18041500" ixy="-0.00245700" ixz="0.00100800" iyy="37.53872500" iyz="14.36120200" izz="25.73444400"/>
      <origin rpy="0 0 0" xyz="-0.034 -50.76 59.953"/>
    </inertial>
    <collision>
      <geometry>
        <mesh filename="package://xMateCR12_description/meshes/xMateCR12_link3.stl" scale="0.001 0.001 0.001"/>
      </geometry>
      <origin rpy="0 0 0" xyz="0 0 0"/>
    </collision>
  </link>
  <joint name="xMateCR12_joint_4" type="revolute">
    <parent link="xMateCR12_link3"/>
    <child link="xMateCR12_link4"/>
    <limit effort="102" lower="-3.0543" upper="3.0543" velocity="23.4"/>
    <!--     lower="-3.0543" upper="3.0543" -->
    <axis xyz="0 0 1"/>
    <!--     <origin rpy="0 0 0" xyz=0.0 0.0 0.54/> -->
    <origin rpy="0 0 0" xyz="0.0 0.0 0.54"/>
  </joint>
  <transmission name="tran4">
    <type>transmission_interface/SimpleTransmission</type>
    <joint name="xmate_joint_4">
      <hardwareInterface>EffortJointInterface</hardwareInterface>
    </joint>
    <actuator name="motor4">
      <hardwareInterface>EffortJointInterface</hardwareInterface>
      <mechanicalReduction>1</mechanicalReduction>
    </actuator>
  </transmission>
  <!--link 4-->
  <link name="xMateCR12_link4">
    <visual>
      <geometry>
        <mesh filename="package://xMateCR12_description/meshes/xMateCR12_link4.stl" scale=".001 0.001 0.001"/>
      </geometry>
      <origin rpy="0 0 0" xyz="0.0 0.0 0.0"/>
      <material name="white"/>
    </visual>
    <inertial>
      <mass value="4.015"/>
      <inertia ixx="98.62021500" ixy="0.01911600" ixz="-0.03049000" iyy="97.20569800" iyz="8.09217100" izz="9.30672300"/>
      <origin rpy="0 0 0" xyz="-0.074 12.412 -165.484"/>
    </inertial>
    <collision>
      <geometry>
        <mesh filename="package://xMateCR12_description/meshes/xMateCR12_link4.stl" scale="0.001 0.001 0.001"/>
      </geometry>
      <origin rpy="0 0 0" xyz="0.0 0.0 0.0"/>
    </collision>
  </link>
  <joint name="xMateCR12_joint_5" type="revolute">
    <parent link="xMateCR12_link4"/>
    <child link="xMateCR12_link5"/>
    <limit effort="66" lower="-3.0543" upper="3.0543" velocity="24.0"/>
    <axis xyz="0 -1 0"/>
    <origin rpy="0 0 0" xyz="0.0 -0.15 0.0"/>
  </joint>
  <transmission name="tran5">
    <type>transmission_interface/SimpleTransmission</type>
    <joint name="xmate_joint_5">
      <hardwareInterface>EffortJointInterface</hardwareInterface>
    </joint>
    <actuator name="motor5">
      <hardwareInterface>EffortJointInterface</hardwareInterface>
      <mechanicalReduction>1</mechanicalReduction>
    </actuator>
  </transmission>
  <!--link 5-->
  <link name="xMateCR12_link5">
    <visual>
      <geometry>
        <mesh filename="package://xMateCR12_description/meshes/xMateCR12_link5.stl" scale="0.001 0.001 0.001"/>
      </geometry>
      <origin rpy="0 0 0" xyz="0 0 0"/>
      <material name="white"/>
    </visual>
    <inertial>
      <mass value="2.34"/>
      <inertia ixx="9.53362900" ixy="-0.00282100" ixz="0.00824000" iyy="5.81554500" iyz="0.99717400" izz="6.92084900"/>
      <origin rpy="0 0 0" xyz="-0.043 -31.099 14.133"/>
    </inertial>
    <collision>
      <geometry>
        <mesh filename="package://xMateCR12_description/meshes/xMateCR12_link5.stl" scale="0.001 0.001 0.001"/>
      </geometry>
      <origin rpy="0 0 0" xyz="0 0 0"/>
    </collision>
  </link>
  <joint name="xMateCR12_joint_6" type="revolute">
    <parent link="xMateCR12_link5"/>
    <child link="xMateCR12_link6"/>
    <limit effort="66" lower="-3.0543" upper="3.0543" velocity="24.0"/>
    <axis xyz="0 0 1"/>
    <origin rpy="0.0 0.0 0" xyz="0.0 0.0 0.127"/>
  </joint>
  <transmission name="tran6">
    <type>transmission_interface/SimpleTransmission</type>
    <joint name="xmate_joint_6">
      <hardwareInterface>EffortJointInterface</hardwareInterface>
    </joint>
    <actuator name="motor6">
      <hardwareInterface>EffortJointInterface</hardwareInterface>
      <mechanicalReduction>1</mechanicalReduction>
    </actuator>
  </transmission>
  <!--link 6-->
  <link name="xMateCR12_link6">
    <visual>
      <geometry>
        <mesh filename="package://xMateCR12_description/meshes/xMateCR12_link6.stl" scale="0.001 0.001 0.001"/>
      </geometry>
      <origin rpy="0 0 0" xyz="0.0 0.0 0.0"/>
      <material name="white"/>
    </visual>
    <inertial>
      <mass value="1.142"/>
      <inertia ixx="2.17743100" ixy="-0.00017800" ixz="-0.00015500" iyy="2.18830000" iyz="-0.00570300" izz="1.25122000"/>
      <origin rpy="0 0 0" xyz="0.001 -0.201 -49.302"/>
    </inertial>
    <collision>
      <geometry>
        <mesh filename="package://xMateCR12_description/meshes/xMateCR12_link6.stl" scale="0.001 0.001 0.001"/>
      </geometry>
      <origin rpy="0 0 0" xyz="0.0 0.0 0.0"/>
    </collision>
  </link>
</robot>
