<robot xmlns:xacro="http://www.ros.org/wiki/xacro" name="xMateCR7">
  <!-- Constants for robot dimensions -->
  <material name="black">
    <color rgba="0.0 0.0 0.0 1.0"/>
  </material>
  <material name="blue">
    <color rgba="0.0 0.0 0.8 1.0"/>
  </material>
  <material name="green">
    <color rgba="0.0 0.8 0.0 1.0"/>
  </material>
  <material name="grey">
    <color rgba="0.2 0.2 0.2 1.0"/>
  </material>
  <material name="orange">
    <color rgba="1.0 0.423529411765 0.0392156862745 1.0"/>
  </material>
  <material name="brown">
    <color rgba="0.870588235294 0.811764705882 0.764705882353 1.0"/>
  </material>
  <material name="red">
    <color rgba="0.8 0.0 0.0 1.0"/>
  </material>
  <material name="white">
    <color rgba="1.0 1.0 1.0 1.0"/>
  </material>
  <material name="Beige">
    <color rgba="1.0 0.784 0.5765 1.0"/>
  </material>
  <!-- Used for fixing robot to Gazebo 'base_link' -->
  <link name="world"/>
  <joint name="fixed" type="fixed">
    <parent link="world"/>
    <child link="xMateCR7_base"/>
  </joint>
  <!--base-->
  <link name="xMateCR7_base">
    <visual>
      <geometry>
        <mesh filename="package://xMateCR7_description/meshes/xMateCR7_base.stl" scale="0.001 0.001 0.001"/>
      </geometry>
      <origin rpy="0 0 0" xyz="0.0 0.0 0.0"/>
      <material name="white"/>
    </visual>
    <inertial>
      <mass value="5.489"/>
      <inertia ixx="49.30386700" ixy="-0.01089900" ixz="0.00512200" iyy="37.22178900" iyz="13.26200300" izz="28.23666200"/>
      <origin rpy="0 0 0" xyz="-0.006 35.426 227.861"/>
    </inertial>
    <collision>
      <geometry>
        <mesh filename="package://xMateCR7_description/meshes/xMateCR7_base.stl" scale="0.001 0.001 0.001"/>
      </geometry>
      <origin rpy="0 0 0" xyz="0.0 0.0 0.0"/>
    </collision>
  </link>
  <joint name="xMateCR7_joint_1" type="revolute">
    <parent link="xMateCR7_base"/>
    <child link="xMateCR7_link1"/>
    <limit effort="194" lower="-3.0543" upper="3.0543" velocity="18.0"/>
    <axis xyz="0 0 1"/>
    <origin rpy="0 0 0" xyz="0.0 0.0 0.0"/>
  </joint>
  <transmission name="tran1">
    <type>transmission_interface/SimpleTransmission</type>
    <joint name="xMateCR7_joint_7">
      <hardwareInterface>EffortJointInterface</hardwareInterface>
    </joint>
    <actuator name="motor1">
      <hardwareInterface>EffortJointInterface</hardwareInterface>
      <mechanicalReduction>1</mechanicalReduction>
    </actuator>
  </transmission>
  <!--link 1-->
  <link name="xMateCR7_link1">
    <visual>
      <geometry>
        <mesh filename="package://xMateCR7_description/meshes/xMateCR7_link1.stl" scale="0.001 0.001 0.001"/>
      </geometry>
      <origin rpy="0 0 0" xyz="0 0 0"/>
      <material name="white"/>
    </visual>
    <inertial>
      <mass value="5.489"/>
      <inertia ixx="49.30386700" ixy="-0.01089900" ixz="0.00512200" iyy="37.22178900" iyz="13.26200300" izz="28.23666200"/>
      <origin rpy="0 0 0" xyz="-0.006 35.426 227.861"/>
    </inertial>
    <collision>
      <geometry>
        <mesh filename="package://xMateCR7_description/meshes/xMateCR7_link1.stl" scale="0.001 0.001 0.001"/>
      </geometry>
      <origin rpy="0 0 0" xyz="0 0 0"/>
    </collision>
  </link>
  <joint name="xMateCR7_joint_2" type="revolute">
    <parent link="xMateCR7_link1"/>
    <child link="xMateCR7_link2"/>
    <limit effort="194" lower="-3.0543" upper="3.0543" velocity="18.0"/>
    <axis xyz="0 1 0"/>
    <origin rpy="0 0 0" xyz="0.0 0.0 0.296"/>
  </joint>
  <transmission name="tran2">
    <type>transmission_interface/SimpleTransmission</type>
    <joint name="xmate_joint_2">
      <hardwareInterface>EffortJointInterface</hardwareInterface>
    </joint>
    <actuator name="motor2">
      <hardwareInterface>EffortJointInterface</hardwareInterface>
      <mechanicalReduction>1</mechanicalReduction>
    </actuator>
  </transmission>
  <!--link 2-->
  <link name="xMateCR7_link2">
    <visual>
      <geometry>
        <mesh filename="package://xMateCR7_description/meshes/xMateCR7_link2.stl" scale="0.001 0.001 0.001"/>
      </geometry>
      <origin rpy="0 0 0" xyz="0 0 0.0"/>
      <material name="white"/>
    </visual>
    <inertial>
      <mass value="7.281"/>
      <inertia ixx="342.18338500" ixy="-0.00242900" ixz="-0.05916000" iyy="337.34901700" iyz="7.46656200" izz="25.16473700"/>
      <origin rpy="0 0 0" xyz="-0.006 155.018 199.572"/>
    </inertial>
    <collision>
      <geometry>
        <mesh filename="package://xMateCR7_description/meshes/xMateCR7_link2.stl" scale="0.001 0.001 0.001"/>
      </geometry>
      <origin rpy="0 0 0" xyz="0 0 0.0"/>
    </collision>
  </link>
  <joint name="xMateCR7_joint_3" type="revolute">
    <parent link="xMateCR7_link2"/>
    <child link="xMateCR7_link3"/>
    <limit effort="102" lower="-3.0543" upper="3.0543" velocity="23.4"/>
    <axis xyz="0 -1 0"/>
    <origin rpy="0 0 0" xyz="0.0 0.0 0.49"/>
  </joint>
  <transmission name="tran3">
    <type>transmission_interface/SimpleTransmission</type>
    <joint name="xmate_joint_3">
      <hardwareInterface>EffortJointInterface</hardwareInterface>
    </joint>
    <actuator name="motor3">
      <hardwareInterface>EffortJointInterface</hardwareInterface>
      <mechanicalReduction>1</mechanicalReduction>
    </actuator>
  </transmission>
  <!--link 3-->
  <link name="xMateCR7_link3">
    <visual>
      <geometry>
        <mesh filename="package://xMateCR7_description/meshes/xMateCR7_link3.stl" scale="0.001 0.001 0.001"/>
      </geometry>
      <origin rpy="0 0 0" xyz="0 0 0"/>
      <material name="white"/>
    </visual>
    <inertial>
      <mass value="2.872"/>
      <inertia ixx="20.89959400" ixy="-0.00192500" ixz="0.00024200" iyy="13.07616600" iyz="6.29374200" izz="12.13645500"/>
      <origin rpy="0 0 0" xyz="-0.012 -44.249 48.945"/>
    </inertial>
    <collision>
      <geometry>
        <mesh filename="package://xMateCR7_description/meshes/xMateCR7_link3.stl" scale="0.001 0.001 0.001"/>
      </geometry>
      <origin rpy="0 0 0" xyz="0 0 0"/>
    </collision>
  </link>
  <joint name="xMateCR7_joint_4" type="revolute">
    <parent link="xMateCR7_link3"/>
    <child link="xMateCR7_link4"/>
    <limit effort="66" lower="-3.0543" upper="3.0543" velocity="24.0"/>
    <!--     lower="-3.0543" upper="3.0543" -->
    <axis xyz="0 0 1"/>
    <!--     <origin rpy="0 0 0" xyz=0.0 0.0 0.36/> -->
    <origin rpy="0 0 0" xyz="0.0 0.0 0.36"/>
  </joint>
  <transmission name="tran4">
    <type>transmission_interface/SimpleTransmission</type>
    <joint name="xmate_joint_4">
      <hardwareInterface>EffortJointInterface</hardwareInterface>
    </joint>
    <actuator name="motor4">
      <hardwareInterface>EffortJointInterface</hardwareInterface>
      <mechanicalReduction>1</mechanicalReduction>
    </actuator>
  </transmission>
  <!--link 4-->
  <link name="xMateCR7_link4">
    <visual>
      <geometry>
        <mesh filename="package://xMateCR7_description/meshes/xMateCR7_link4.stl" scale=".001 0.001 0.001"/>
      </geometry>
      <origin rpy="0 0 0" xyz="0.0 0.0 0.0"/>
      <material name="white"/>
    </visual>
    <inertial>
      <mass value="2.823"/>
      <inertia ixx="31.66823400" ixy="-0.00022300" ixz="-0.00043700" iyy="30.30475500" iyz="4.36787800" izz="5.68926400"/>
      <origin rpy="0 0 0" xyz="0.024 18.331 -86.517"/>
    </inertial>
    <collision>
      <geometry>
        <mesh filename="package://xMateCR7_description/meshes/xMateCR7_link4.stl" scale="0.001 0.001 0.001"/>
      </geometry>
      <origin rpy="0 0 0" xyz="0.0 0.0 0.0"/>
    </collision>
  </link>
  <joint name="xMateCR7_joint_5" type="revolute">
    <parent link="xMateCR7_link4"/>
    <child link="xMateCR7_link5"/>
    <limit effort="66" lower="-3.0543" upper="3.0543" velocity="24.0"/>
    <axis xyz="0 -1 0"/>
    <origin rpy="0 0 0" xyz="0.0 -0.15 0.004"/>
  </joint>
  <transmission name="tran5">
    <type>transmission_interface/SimpleTransmission</type>
    <joint name="xmate_joint_5">
      <hardwareInterface>EffortJointInterface</hardwareInterface>
    </joint>
    <actuator name="motor5">
      <hardwareInterface>EffortJointInterface</hardwareInterface>
      <mechanicalReduction>1</mechanicalReduction>
    </actuator>
  </transmission>
  <!--link 5-->
  <link name="xMateCR7_link5">
    <visual>
      <geometry>
        <mesh filename="package://xMateCR7_description/meshes/xMateCR7_link5.stl" scale="0.001 0.001 0.001"/>
      </geometry>
      <origin rpy="0 0 0" xyz="0 0 0"/>
      <material name="white"/>
    </visual>
    <inertial>
      <mass value="2.366"/>
      <inertia ixx="9.28562900" ixy="-0.00272800" ixz="0.00818400" iyy="5.75628400" iyz="0.98839500" izz="6.67332000"/>
      <origin rpy="0 0 0" xyz="-0.042 -29.723 14.573"/>
    </inertial>
    <collision>
      <geometry>
        <mesh filename="package://xMateCR7_description/meshes/xMateCR7_link5.stl" scale="0.001 0.001 0.001"/>
      </geometry>
      <origin rpy="0 0 0" xyz="0 0 0"/>
    </collision>
  </link>
  <joint name="xMateCR7_joint_6" type="revolute">
    <parent link="xMateCR7_link5"/>
    <child link="xMateCR7_link6"/>
    <limit effort="29" lower="-3.0543" upper="3.0543" velocity="30.0"/>
    <axis xyz="0 0 1"/>
    <origin rpy="0.0 0.0 0" xyz="0.0 0.0 0.123"/>
  </joint>
  <transmission name="tran6">
    <type>transmission_interface/SimpleTransmission</type>
    <joint name="xmate_joint_6">
      <hardwareInterface>EffortJointInterface</hardwareInterface>
    </joint>
    <actuator name="motor6">
      <hardwareInterface>EffortJointInterface</hardwareInterface>
      <mechanicalReduction>1</mechanicalReduction>
    </actuator>
  </transmission>
  <!--link 6-->
  <link name="xMateCR7_link6">
    <visual>
      <geometry>
        <mesh filename="package://xMateCR7_description/meshes/xMateCR7_link6.stl" scale="0.001 0.001 0.001"/>
      </geometry>
      <origin rpy="0 0 0" xyz="0.0 0.0 0.0"/>
      <material name="white"/>
    </visual>
    <inertial>
      <mass value="1.086"/>
      <inertia ixx="2.00140300" ixy="-0.00007500" ixz="-0.00002200" iyy="2.01206100" iyz="-0.00521000" izz="1.22288500"/>
      <origin rpy="0 0 0" xyz="0.009 -0.199 -48.276"/>
    </inertial>
    <collision>
      <geometry>
        <mesh filename="package://xMateCR7_description/meshes/xMateCR7_link6.stl" scale="0.001 0.001 0.001"/>
      </geometry>
      <origin rpy="0 0 0" xyz="0.0 0.0 0.0"/>
    </collision>
  </link>
</robot>
